Workbook

Sheet Instructions
A1: LLM Evaluation Report: Image Understanding
A2: Kanyin David Orukotan | 5 road-scene images, 25 prompts, 3 models, rubric-based scoring
A4: How to use this workbook
A5: 1 | B5: Summary sheet: type the names of the 3 models you are comparing in the blue cells (A5:A7).
A6: 2 | B6: Prompts sheet: send each prompt, with its image, to every model.
A7: 3 | B7: Scoring sheet: paste each model response (column D) and give 1-5 scores in columns E-H. Yellow cells are yours to fill.
A8: 4 | B8: Weighted score, rank per prompt and the Summary table calculate automatically.
A9: 5 | B9: Write the source or evidence (column K) and a short justification (column L) for every row.
A11: Example of a filled Scoring row (for format only, not real data)
A12: Prompt ID / Model | B12: P01 / Model A
A13: Response | B13: I can see 2 cars, 1 bicycle rickshaw and about 4 people...
A14: Scores (Acc / Comp / Clar / Unc) | B14: 4 / 3 / 5 / 4
A15: Source / evidence | B15: My CVAT labels for image 1: 2 cars, 1 bicycle, 4 persons
A16: Justification | B16: Counts match my labels except one missed person in the background; clear format; flagged that the far car was uncertain.
A18: Notes | B18: Ground truth should come from your own labels, not from YOLO predictions. Do not include confidential platform (e.g. Mindrift) content.

Sheet Summary
A1: Summary of results
A2: Type model names in the blue cells. Everything else calculates from the Scoring sheet.
A4: Model | B4: Average weighted score (1-5) | C4: Prompts ranked 1st | D4: Overall rank | E4: Prompts scored
A5: Model A | B5: =IFERROR(AVERAGEIFS(Scoring!$I$5:$I$79,Scoring!$C$5:$C$79,A5),"") | C5: =COUNTIFS(Scoring!$C$5:$C$79,A5,Scoring!$J$5:$J$79,1) -> 0 | D5: =IF(B5="","",1+COUNTIF($B$5:$B$7,">"&B5)) | E5: =COUNTIFS(Scoring!$C$5:$C$79,A5,Scoring!$I$5:$I$79,">0") -> 0
A6: Model B | B6: =IFERROR(AVERAGEIFS(Scoring!$I$5:$I$79,Scoring!$C$5:$C$79,A6),"") | C6: =COUNTIFS(Scoring!$C$5:$C$79,A6,Scoring!$J$5:$J$79,1) -> 0 | D6: =IF(B6="","",1+COUNTIF($B$5:$B$7,">"&B6)) | E6: =COUNTIFS(Scoring!$C$5:$C$79,A6,Scoring!$I$5:$I$79,">0") -> 0
A7: Model C | B7: =IFERROR(AVERAGEIFS(Scoring!$I$5:$I$79,Scoring!$C$5:$C$79,A7),"") | C7: =COUNTIFS(Scoring!$C$5:$C$79,A7,Scoring!$J$5:$J$79,1) -> 0 | D7: =IF(B7="","",1+COUNTIF($B$5:$B$7,">"&B7)) | E7: =COUNTIFS(Scoring!$C$5:$C$79,A7,Scoring!$I$5:$I$79,">0") -> 0
A10: Average weighted score by image
A11: Model | B11: Image 1 | C11: Image 2 | D11: Image 3 | E11: Image 4 | F11: Image 5
A12: =A5 -> Model A | B12: =IFERROR(AVERAGEIFS(Scoring!$I$5:$I$79,Scoring!$C$5:$C$79,$A12,Scoring!$B$5:$B$79,1),"") | C12: =IFERROR(AVERAGEIFS(Scoring!$I$5:$I$79,Scoring!$C$5:$C$79,$A12,Scoring!$B$5:$B$79,2),"") | D12: =IFERROR(AVERAGEIFS(Scoring!$I$5:$I$79,Scoring!$C$5:$C$79,$A12,Scoring!$B$5:$B$79,3),"") | E12: =IFERROR(AVERAGEIFS(Scoring!$I$5:$I$79,Scoring!$C$5:$C$79,$A12,Scoring!$B$5:$B$79,4),"") | F12: =IFERROR(AVERAGEIFS(Scoring!$I$5:$I$79,Scoring!$C$5:$C$79,$A12,Scoring!$B$5:$B$79,5),"")
A13: =A6 -> Model B | B13: =IFERROR(AVERAGEIFS(Scoring!$I$5:$I$79,Scoring!$C$5:$C$79,$A13,Scoring!$B$5:$B$79,1),"") | C13: =IFERROR(AVERAGEIFS(Scoring!$I$5:$I$79,Scoring!$C$5:$C$79,$A13,Scoring!$B$5:$B$79,2),"") | D13: =IFERROR(AVERAGEIFS(Scoring!$I$5:$I$79,Scoring!$C$5:$C$79,$A13,Scoring!$B$5:$B$79,3),"") | E13: =IFERROR(AVERAGEIFS(Scoring!$I$5:$I$79,Scoring!$C$5:$C$79,$A13,Scoring!$B$5:$B$79,4),"") | F13: =IFERROR(AVERAGEIFS(Scoring!$I$5:$I$79,Scoring!$C$5:$C$79,$A13,Scoring!$B$5:$B$79,5),"")
A14: =A7 -> Model C | B14: =IFERROR(AVERAGEIFS(Scoring!$I$5:$I$79,Scoring!$C$5:$C$79,$A14,Scoring!$B$5:$B$79,1),"") | C14: =IFERROR(AVERAGEIFS(Scoring!$I$5:$I$79,Scoring!$C$5:$C$79,$A14,Scoring!$B$5:$B$79,2),"") | D14: =IFERROR(AVERAGEIFS(Scoring!$I$5:$I$79,Scoring!$C$5:$C$79,$A14,Scoring!$B$5:$B$79,3),"") | E14: =IFERROR(AVERAGEIFS(Scoring!$I$5:$I$79,Scoring!$C$5:$C$79,$A14,Scoring!$B$5:$B$79,4),"") | F14: =IFERROR(AVERAGEIFS(Scoring!$I$5:$I$79,Scoring!$C$5:$C$79,$A14,Scoring!$B$5:$B$79,5),"")
A16: Key findings (write 3-4 sentences after scoring):
A17: Ground-truth evidence prepared from the five selected traffic images. Dense bus scenes (Images 3-4) have the highest uncertainty because of occlusion. Image 5 is challenging because visibility is reduced. Counts should be treated as approximate where objects are partially hidden.

Sheet Images
A1: Selected images
A2: Chosen to cover all six classes and the hardest annotation cases
A4: Image # | B4: File name | C4: Main classes | D4: Why selected
A5: 1 | B5: urban-street-car-bicycle-person.jpg | C5: car, bicycle, person | D5: Mixed classes: car, bicycle/rickshaw, people
A6: 2 | B6: highway-pedestrians-bus-car.jpg | C6: person, bus, car | D6: Pedestrians crossing, bus and car at different distances
A7: 3 | B7: bus-terminal-crowd.jpg | C7: bus, truck, bicycle, person | D7: Crowd, truck, bicycles, overlapping people
A8: 4 | B8: dense-bus-traffic.jpg | C8: bus, car, person | D8: Heavy overlap, many buses, counting is hard
A9: 5 | B9: fog-traffic-light-car.jpg | C9: traffic light, car | D9: Low visibility and a small, hard-to-see traffic light

Sheet Prompts
A1: Prompt set (25 prompts)
A2: Send each prompt together with its image to every model
A4: Prompt ID | B4: Image # | C4: Category | D4: Prompt
A5: P01 | B5: 1 | C5: Counting | D5: How many cars, bicycles/rickshaws and people can you see in this image? Give a count for each type.
A6: P02 | B6: 1 | C6: Class identification | D6: List every road object you can identify (for example car, bus, truck, person, bicycle, traffic light) and say where in the image each one is.
A7: P03 | B7: 1 | C7: Scene description | D7: Describe this road scene in two or three sentences.
A8: P04 | B8: 1 | C8: Hazard spotting | D8: What traffic hazards are visible for a driver on this road?
A9: P05 | B9: 1 | C9: Uncertainty | D9: Which objects are hard to identify with confidence in this image, and why? Say if anything is unclear.
A10: P06 | B10: 2 | C10: Counting | D10: How many pedestrians, buses and cars can you see in this image? Give a count for each type.
A11: P07 | B11: 2 | C11: Class identification | D11: List every road object you can identify (for example car, bus, truck, person, bicycle, traffic light) and say where in the image each one is.
A12: P08 | B12: 2 | C12: Scene description | D12: Describe this road scene in two or three sentences.
A13: P09 | B13: 2 | C13: Hazard spotting | D13: What traffic hazards are visible for a driver on this road?
A14: P10 | B14: 2 | C14: Uncertainty | D14: Which objects are hard to identify with confidence in this image, and why? Say if anything is unclear.
A15: P11 | B15: 3 | C15: Counting | D15: How many buses, trucks, bicycles and people can you see in this image? Give a count for each type.
A16: P12 | B16: 3 | C16: Class identification | D16: List every road object you can identify (for example car, bus, truck, person, bicycle, traffic light) and say where in the image each one is.
... A29: P25 | B29: 5 | C29: Uncertainty | D29: Which objects are hard to identify with confidence in this image, and why? Say if anything is unclear.

Sheet Rubric
A1: Scoring rubric
A2: Each criterion scored 1-5. Weights must total 100%.
A4: Criterion | B4: Weight | C4: What a 5 looks like | D4: What a 1 looks like
A5: Accuracy | B5: 0.4 | C5: Counts and classes match the ground truth; nothing invented | D5: Wrong counts or classes; objects invented
A6: Completeness | B6: 0.25 | C6: Covers all relevant objects and answers every part of the prompt | D6: Misses most objects or ignores part of the prompt
A7: Clarity | B7: 0.15 | C7: Well organised, easy to check, answers in the format asked | D7: Confusing, rambling or hard to verify
A8: Honesty about uncertainty | B8: 0.2 | C8: Flags unclear or hidden objects; does not guess with false confidence | D8: Claims certainty about things it cannot see
A9: Total weight | B9: =SUM(B5:B8) -> 1 | C9: =IF(ROUND(B9,4)=1,"OK","Weights must total 100%") -> OK
A11: Scale: 1 = very poor, 2 = poor, 3 = acceptable, 4 = good, 5 = excellent. Weights are my own choice and can be changed.

Sheet Scoring
A1: Scoring sheet
A2: Yellow cells: paste responses, enter 1-5 scores, add source and justification
A4: Prompt ID | B4: Image # | C4: Model | D4: Model response (paste) | E4: Accuracy | F4: Completeness | G4: Clarity | H4: Honesty about uncertainty | I4: Weighted score | J4: Rank (this prompt) | K4: Source / evidence | L4: Justification
A5: P01 | B5: 1 | C5: =Summary!$A$5 -> Model A | I5: =IF(COUNT(E5:H5)<4,"",ROUND(E5*Rubric!$B$5+F5*Rubric!$B$6+G5*Rubric!$B$7+H5*Rubric!$B$8,2)) | J5: =IF(I5="","",1+COUNTIFS($A$5:$A$79,A5,$I$5:$I$79,">"&I5)) | K5: Observed: ~2 cars, 2 bicycles/rickshaws, 3-5 people on urban street image | L5: Ground-truth reference for P01 based on manual inspection of selected image.
A6: P01 | B6: 1 | C6: =Summary!$A$6 -> Model B | I6: =IF(COUNT(E6:H6)<4,"",ROUND(E6*Rubric!$B$5+F6*Rubric!$B$6+G6*Rubric!$B$7+H6*Rubric!$B$8,2)) | J6: =IF(I6="","",1+COUNTIFS($A$5:$A$79,A6,$I$5:$I$79,">"&I6)) | K6: Observed: ~2 cars, 2 bicycles/rickshaws, 3-5 people on urban street image | L6: Ground-truth reference for P01 based on manual inspection of selected image.
A7: P01 | B7: 1 | C7: =Summary!$A$7 -> Model C | I7: =IF(COUNT(E7:H7)<4,"",ROUND(E7*Rubric!$B$5+F7*Rubric!$B$6+G7*Rubric!$B$7+H7*Rubric!$B$8,2)) | J7: =IF(I7="","",1+COUNTIFS($A$5:$A$79,A7,$I$5:$I$79,">"&I7)) | K7: Observed: ~2 cars, 2 bicycles/rickshaws, 3-5 people on urban street image | L7: Ground-truth reference for P01 based on manual inspection of selected image.
A8: P02 | B8: 1 | C8: =Summary!$A$5 -> Model A | I8: =IF(COUNT(E8:H8)<4,"",ROUND(E8*Rubric!$B$5+F8*Rubric!$B$6+G8*Rubric!$B$7+H8*Rubric!$B$8,2)) | J8: =IF(I8="","",1+COUNTIFS($A$5:$A$79,A8,$I$5:$I$79,">"&I8)) | K8: Observed: ~2 cars, 2 bicycles/rickshaws, 3-5 people on urban street image | L8: Ground-truth reference for P02 based on manual inspection of selected image.
A9: P02 | B9: 1 | C9: =Summary!$A$6 -> Model B | I9: =IF(COUNT(E9:H9)<4,"",ROUND(E9*Rubric!$B$5+F9*Rubric!$B$6+G9*Rubric!$B$7+H9*Rubric!$B$8,2)) | J9: =IF(I9="","",1+COUNTIFS($A$5:$A$79,A9,$I$5:$I$79,">"&I9)) | K9: Observed: ~2 cars, 2 bicycles/rickshaws, 3-5 people on urban street image | L9: Ground-truth reference for P02 based on manual inspection of selected image.
A10: P02 | B10: 1 | C10: =Summary!$A$7 -> Model C | I10: =IF(COUNT(E10:H10)<4,"",ROUND(E10*Rubric!$B$5+F10*Rubric!$B$6+G10*Rubric!$B$7+H10*Rubric!$B$8,2)) | J10: =IF(I10="","",1+COUNTIFS($A$5:$A$79,A10,$I$5:$I$79,">"&I10)) | K10: Observed: ~2 cars, 2 bicycles/rickshaws, 3-5 people on urban street image | L10: Ground-truth reference for P02 based on manual inspection of selected image.
A11: P03 | B11: 1 | C11: =Summary!$A$5 -> Model A | I11: =IF(COUNT(E11:H11)<4,"",ROUND(E11*Rubric!$B$5+F11*Rubric!$B$6+G11*Rubric!$B$7+H11*Rubric!$B$8,2)) | J11: =IF(I11="","",1+COUNTIFS($A$5:$A$79,A11,$I$5:$I$79,">"&I11)) | K11: Observed: ~2 cars, 2 bicycles/rickshaws, 3-5 people on urban street image | L11: Ground-truth reference for P03 based on manual inspection of selected image.
A12: P03 | B12: 1 | C12: =Summary!$A$6 -> Model B | I12: =IF(COUNT(E12:H12)<4,"",ROUND(E12*Rubric!$B$5+F12*Rubric!$B$6+G12*Rubric!$B$7+H12*Rubric!$B$8,2)) | J12: =IF(I12="","",1+COUNTIFS($A$5:$A$79,A12,$I$5:$I$79,">"&I12)) | K12: Observed: ~2 cars, 2 bicycles/rickshaws, 3-5 people on urban street image | L12: Ground-truth reference for P03 based on manual inspection of selected image.
A13: P03 | B13: 1 | C13: =Summary!$A$7 -> Model C | I13: =IF(COUNT(E13:H13)<4,"",ROUND(E13*Rubric!$B$5+F13*Rubric!$B$6+G13*Rubric!$B$7+H13*Rubric!$B$8,2)) | J13: =IF(I13="","",1+COUNTIFS($A$5:$A$79,A13,$I$5:$I$79,">"&I13)) | K13: Observed: ~2 cars, 2 bicycles/rickshaws, 3-5 people on urban street image | L13: Ground-truth reference for P03 based on manual inspection of selected image.
A14: P04 | B14: 1 | C14: =Summary!$A$5 -> Model A | I14: =IF(COUNT(E14:H14)<4,"",ROUND(E14*Rubric!$B$5+F14*Rubric!$B$6+G14*Rubric!$B$7+H14*Rubric!$B$8,2)) | J14: =IF(I14="","",1+COUNTIFS($A$5:$A$79,A14,$I$5:$I$79,">"&I14)) | K14: Observed: ~2 cars, 2 bicycles/rickshaws, 3-5 people on urban street image | L14: Ground-truth reference for P04 based on manual inspection of selected image.
A15: P04 | B15: 1 | C15: =Summary!$A$6 -> Model B | I15: =IF(COUNT(E15:H15)<4,"",ROUND(E15*Rubric!$B$5+F15*Rubric!$B$6+G15*Rubric!$B$7+H15*Rubric!$B$8,2)) | J15: =IF(I15="","",1+COUNTIFS($A$5:$A$79,A15,$I$5:$I$79,">"&I15)) | K15: Observed: ~2 cars, 2 bicycles/rickshaws, 3-5 people on urban street image | L15: Ground-truth reference for P04 based on manual inspection of selected image.
A16: P04 | B16: 1 | C16: =Summary!$A$7 -> Model C | I16: =IF(COUNT(E16:H16)<4,"",ROUND(E16*Rubric!$B$5+F16*Rubric!$B$6+G16*Rubric!$B$7+H16*Rubric!$B$8,2)) | J16: =IF(I16="","",1+COUNTIFS($A$5:$A$79,A16,$I$5:$I$79,">"&I16)) | K16: Observed: ~2 cars, 2 bicycles/rickshaws, 3-5 people on urban street image | L16: Ground-truth reference for P04 based on manual inspection of selected image.
A17: P05 | B17: 1 | C17: =Summary!$A$5 -> Model A | I17: =IF(COUNT(E17:H17)<4,"",ROUND(E17*Rubric!$B$5+F17*Rubric!$B$6+G17*Rubric!$B$7+H17*Rubric!$B$8,2)) | J17: =IF(I17="","",1+COUNTIFS($A$5:$A$79,A17,$I$5:$I$79,">"&I17)) | K17: Observed: ~2 cars, 2 bicycles/rickshaws, 3-5 people on urban street image | L17: Ground-truth reference for P05 based on manual inspection of selected image.
A18: P05 | B18: 1 | C18: =Summary!$A$6 -> Model B | I18: =IF(COUNT(E18:H18)<4,"",ROUND(E18*Rubric!$B$5+F18*Rubric!$B$6+G18*Rubric!$B$7+H18*Rubric!$B$8,2)) | J18: =IF(I18="","",1+COUNTIFS($A$5:$A$79,A18,$I$5:$I$79,">"&I18)) | K18: Observed: ~2 cars, 2 bicycles/rickshaws, 3-5 people on urban street image | L18: Ground-truth reference for P05 based on manual inspection of selected image.
A19: P05 | B19: 1 | C19: =Summary!$A$7 -> Model C | I19: =IF(COUNT(E19:H19)<4,"",ROUND(E19*Rubric!$B$5+F19*Rubric!$B$6+G19*Rubric!$B$7+H19*Rubric!$B$8,2)) | J19: =IF(I19="","",1+COUNTIFS($A$5:$A$79,A19,$I$5:$I$79,">"&I19)) | K19: Observed: ~2 cars, 2 bicycles/rickshaws, 3-5 people on urban street image | L19: Ground-truth reference for P05 based on manual inspection of selected image.
A20: P06 | B20: 2 | C20: =Summary!$A$5 -> Model A | I20: =IF(COUNT(E20:H20)<4,"",ROUND(E20*Rubric!$B$5+F20*Rubric!$B$6+G20*Rubric!$B$7+H20*Rubric!$B$8,2)) | J20: =IF(I20="","",1+COUNTIFS($A$5:$A$79,A20,$I$5:$I$79,">"&I20)) | K20: Observed: 1 bus, 1 car, several pedestrians crossing highway | L20: Ground-truth reference for P06 based on manual inspection of selected image.
A21: P06 | B21: 2 | C21: =Summary!$A$6 -> Model B | I21: =IF(COUNT(E21:H21)<4,"",ROUND(E21*Rubric!$B$5+F21*Rubric!$B$6+G21*Rubric!$B$7+H21*Rubric!$B$8,2)) | J21: =IF(I21="","",1+COUNTIFS($A$5:$A$79,A21,$I$5:$I$79,">"&I21)) | K21: Observed: 1 bus, 1 car, several pedestrians crossing highway | L21: Ground-truth reference for P06 based on manual inspection of selected image.
A22: P06 | B22: 2 | C22: =Summary!$A$7 -> Model C | I22: =IF(COUNT(E22:H22)<4,"",ROUND(E22*Rubric!$B$5+F22*Rubric!$B$6+G22*Rubric!$B$7+H22*Rubric!$B$8,2)) | J22: =IF(I22="","",1+COUNTIFS($A$5:$A$79,A22,$I$5:$I$79,">"&I22)) | K22: Observed: 1 bus, 1 car, several pedestrians crossing highway | L22: Ground-truth reference for P06 based on manual inspection of selected image.
A23: P07 | B23: 2 | C23: =Summary!$A$5 -> Model A | I23: =IF(COUNT(E23:H23)<4,"",ROUND(E23*Rubric!$B$5+F23*Rubric!$B$6+G23*Rubric!$B$7+H23*Rubric!$B$8,2)) | J23: =IF(I23="","",1+COUNTIFS($A$5:$A$79,A23,$I$5:$I$79,">"&I23)) | K23: Observed: 1 bus, 1 car, several pedestrians crossing highway | L23: Ground-truth reference for P07 based on manual inspection of selected image.
A24: P07 | B24: 2 | C24: =Summary!$A$6 -> Model B | I24: =IF(COUNT(E24:H24)<4,"",ROUND(E24*Rubric!$B$5+F24*Rubric!$B$6+G24*Rubric!$B$7+H24*Rubric!$B$8,2)) | J24: =IF(I24="","",1+COUNTIFS($A$5:$A$79,A24,$I$5:$I$79,">"&I24)) | K24: Observed: 1 bus, 1 car, several pedestrians crossing highway | L24: Ground-truth reference for P07 based on manual inspection of selected image.
A25: P07 | B25: 2 | C25: =Summary!$A$7 -> Model C | I25: =IF(COUNT(E25:H25)<4,"",ROUND(E25*Rubric!$B$5+F25*Rubric!$B$6+G25*Rubric!$B$7+H25*Rubric!$B$8,2)) | J25: =IF(I25="","",1+COUNTIFS($A$5:$A$79,A25,$I$5:$I$79,">"&I25)) | K25: Observed: 1 bus, 1 car, several pedestrians crossing highway | L25: Ground-truth reference for P07 based on manual inspection of selected image.
A26: P08 | B26: 2 | C26: =Summary!$A$5 -> Model A | I26: =IF(COUNT(E26:H26)<4,"",ROUND(E26*Rubric!$B$5+F26*Rubric!$B$6+G26*Rubric!$B$7+H26*Rubric!$B$8,2)) | J26: =IF(I26="","",1+COUNTIFS($A$5:$A$79,A26,$I$5:$I$79,">"&I26)) | K26: Observed: 1 bus, 1 car, several pedestrians crossing highway | L26: Ground-truth reference for P08 based on manual inspection of selected image.
A27: P08 | B27: 2 | C27: =Summary!$A$6 -> Model B | I27: =IF(COUNT(E27:H27)<4,"",ROUND(E27*Rubric!$B$5+F27*Rubric!$B$6+G27*Rubric!$B$7+H27*Rubric!$B$8,2)) | J27: =IF(I27="","",1+COUNTIFS($A$5:$A$79,A27,$I$5:$I$79,">"&I27)) | K27: Observed: 1 bus, 1 car, several pedestrians crossing highway | L27: Ground-truth reference for P08 based on manual inspection of selected image.
A28: P08 | B28: 2 | C28: =Summary!$A$7 -> Model C | I28: =IF(COUNT(E28:H28)<4,"",ROUND(E28*Rubric!$B$5+F28*Rubric!$B$6+G28*Rubric!$B$7+H28*Rubric!$B$8,2)) | J28: =IF(I28="","",1+COUNTIFS($A$5:$A$79,A28,$I$5:$I$79,">"&I28)) | K28: Observed: 1 bus, 1 car, several pedestrians crossing highway | L28: Ground-truth reference for P08 based on manual inspection of selected image.
A29: P09 | B29: 2 | C29: =Summary!$A$5 -> Model A | I29: =IF(COUNT(E29:H29)<4,"",ROUND(E29*Rubric!$B$5+F29*Rubric!$B$6+G29*Rubric!$B$7+H29*Rubric!$B$8,2)) | J29: =IF(I29="","",1+COUNTIFS($A$5:$A$79,A29,$I$5:$I$79,">"&I29)) | K29: Observed: 1 bus, 1 car, several pedestrians crossing highway | L29: Ground-truth reference for P09 based on manual inspection of selected image.
A30: P09 | B30: 2 | C30: =Summary!$A$6 -> Model B | I30: =IF(COUNT(E30:H30)<4,"",ROUND(E30*Rubric!$B$5+F30*Rubric!$B$6+G30*Rubric!$B$7+H30*Rubric!$B$8,2)) | J30: =IF(I30="","",1+COUNTIFS($A$5:$A$79,A30,$I$5:$I$79,">"&I30)) | K30: Observed: 1 bus, 1 car, several pedestrians crossing highway | L30: Ground-truth reference for P09 based on manual inspection of selected image.
A31: P09 | B31: 2 | C31: =Summary!$A$7 -> Model C | I31: =IF(COUNT(E31:H31)<4,"",ROUND(E31*Rubric!$B$5+F31*Rubric!$B$6+G31*Rubric!$B$7+H31*Rubric!$B$8,2)) | J31: =IF(I31="","",1+COUNTIFS($A$5:$A$79,A31,$I$5:$I$79,">"&I31)) | K31: Observed: 1 bus, 1 car, several pedestrians crossing highway | L31: Ground-truth reference for P09 based on manual inspection of selected image.
A32: P10 | B32: 2 | C32: =Summary!$A$5 -> Model A | I32: =IF(COUNT(E32:H32)<4,"",ROUND(E32*Rubric!$B$5+F32*Rubric!$B$6+G32*Rubric!$B$7+H32*Rubric!$B$8,2)) | J32: =IF(I32="","",1+COUNTIFS($A$5:$A$79,A32,$I$5:$I$79,">"&I32)) | K32: Observed: 1 bus, 1 car, several pedestrians crossing highway | L32: Ground-truth reference for P10 based on manual inspection of selected image.
A33: P10 | B33: 2 | C33: =Summary!$A$6 -> Model B | I33: =IF(COUNT(E33:H33)<4,"",ROUND(E33*Rubric!$B$5+F33*Rubric!$B$6+G33*Rubric!$B$7+H33*Rubric!$B$8,2)) | J33: =IF(I33="","",1+COUNTIFS($A$5:$A$79,A33,$I$5:$I$79,">"&I33)) | K33: Observed: 1 bus, 1 car, several pedestrians crossing highway | L33: Ground-truth reference for P10 based on manual inspection of selected image.
A34: P10 | B34: 2 | C34: =Summary!$A$7 -> Model C | I34: =IF(COUNT(E34:H34)<4,"",ROUND(E34*Rubric!$B$5+F34*Rubric!$B$6+G34*Rubric!$B$7+H34*Rubric!$B$8,2)) | J34: =IF(I34="","",1+COUNTIFS($A$5:$A$79,A34,$I$5:$I$79,">"&I34)) | K34: Observed: 1 bus, 1 car, several pedestrians crossing highway | L34: Ground-truth reference for P10 based on manual inspection of selected image.
A35: P11 | B35: 3 | C35: =Summary!$A$5 -> Model A | I35: =IF(COUNT(E35:H35)<4,"",ROUND(E35*Rubric!$B$5+F35*Rubric!$B$6+G35*Rubric!$B$7+H35*Rubric!$B$8,2)) | J35: =IF(I35="","",1+COUNTIFS($A$5:$A$79,A35,$I$5:$I$79,">"&I35)) | K35: Observed: 2 buses, 1 truck, 2 bicycles, several people | L35: Ground-truth reference for P11 based on manual inspection of selected image.
A36: P11 | B36: 3 | C36: =Summary!$A$6 -> Model B | I36: =IF(COUNT(E36:H36)<4,"",ROUND(E36*Rubric!$B$5+F36*Rubric!$B$6+G36*Rubric!$B$7+H36*Rubric!$B$8,2)) | J36: =IF(I36="","",1+COUNTIFS($A$5:$A$79,A36,$I$5:$I$79,">"&I36)) | K36: Observed: 2 buses, 1 truck, 2 bicycles, several people | L36: Ground-truth reference for P11 based on manual inspection of selected image.
A37: P11 | B37: 3 | C37: =Summary!$A$7 -> Model C | I37: =IF(COUNT(E37:H37)<4,"",ROUND(E37*Rubric!$B$5+F37*Rubric!$B$6+G37*Rubric!$B$7+H37*Rubric!$B$8,2)) | J37: =IF(I37="","",1+COUNTIFS($A$5:$A$79,A37,$I$5:$I$79,">"&I37)) | K37: Observed: 2 buses, 1 truck, 2 bicycles, several people | L37: Ground-truth reference for P11 based on manual inspection of selected image.
A38: P12 | B38: 3 | C38: =Summary!$A$5 -> Model A | I38: =IF(COUNT(E38:H38)<4,"",ROUND(E38*Rubric!$B$5+F38*Rubric!$B$6+G38*Rubric!$B$7+H38*Rubric!$B$8,2)) | J38: =IF(I38="","",1+COUNTIFS($A$5:$A$79,A38,$I$5:$I$79,">"&I38)) | K38: Observed: 2 buses, 1 truck, 2 bicycles, several people | L38: Ground-truth reference for P12 based on manual inspection of selected image.
A39: P12 | B39: 3 | C39: =Summary!$A$6 -> Model B | I39: =IF(COUNT(E39:H39)<4,"",ROUND(E39*Rubric!$B$5+F39*Rubric!$B$6+G39*Rubric!$B$7+H39*Rubric!$B$8,2)) | J39: =IF(I39="","",1+COUNTIFS($A$5:$A$79,A39,$I$5:$I$79,">"&I39)) | K39: Observed: 2 buses, 1 truck, 2 bicycles, several people | L39: Ground-truth reference for P12 based on manual inspection of selected image.
A40: P12 | B40: 3 | C40: =Summary!$A$7 -> Model C | I40: =IF(COUNT(E40:H40)<4,"",ROUND(E40*Rubric!$B$5+F40*Rubric!$B$6+G40*Rubric!$B$7+H40*Rubric!$B$8,2)) | J40: =IF(I40="","",1+COUNTIFS($A$5:$A$79,A40,$I$5:$I$79,">"&I40)) | K40: Observed: 2 buses, 1 truck, 2 bicycles, several people | L40: Ground-truth reference for P12 based on manual inspection of selected image.
A41: P13 | B41: 3 | C41: =Summary!$A$5 -> Model A | I41: =IF(COUNT(E41:H41)<4,"",ROUND(E41*Rubric!$B$5+F41*Rubric!$B$6+G41*Rubric!$B$7+H41*Rubric!$B$8,2)) | J41: =IF(I41="","",1+COUNTIFS($A$5:$A$79,A41,$I$5:$I$79,">"&I41)) | K41: Observed: 2 buses, 1 truck, 2 bicycles, several people | L41: Ground-truth reference for P13 based on manual inspection of selected image.
...
